Workbook
Name List_Owners: 'Lookup Lists'!$A$5:$A$9
Name List_Priority: 'Lookup Lists'!$B$5:$B$8
Name List_Status: 'Lookup Lists'!$C$5:$C$9
Name List_Teams: 'Lookup Lists'!$D$5:$D$12
Name List_Projects: 'Lookup Lists'!$E$5:$E$10
Name List_Releases: 'Lookup Lists'!$F$5:$F$12
Name List_Sprint: 'Lookup Lists'!$G$5:$G$30
Name List_Phase: 'Lookup Lists'!$H$5:$H$11
Name List_Workstream: 'Lookup Lists'!$I$5:$I$11
Name List_Impact: 'Lookup Lists'!$J$5:$J$7
Name List_Probability: 'Lookup Lists'!$K$5:$K$7
Name List_RiskStatus: 'Lookup Lists'!$L$5:$L$8
Name List_DepStatus: 'Lookup Lists'!$M$5:$M$8
Name List_Category: 'Lookup Lists'!$N$5:$N$10

Sheet Dashboard
A1: FY27 ENGINEERING EXECUTIVE DASHBOARD | P1: CHART DATA (do not delete)
A2: Governance view | 01 Jul 2026 – 30 Jun 2027 | All KPIs formula-linked to Project Tracker · Refresh values by recalculating workbook
P3: Status | Q3: Count
B4: Total Projects | D4: Total Tasks | F4: Completed | H4: In Progress | J4: Blocked | L4: At Risk | P4: Not Started | Q4: =COUNTIF('Project Tracker'!$M$5:$M$113,P4)
B5: =COUNTA('Lookup Lists'!$E$5:$E$10) | D5: =COUNTA('Project Tracker'!$A$5:$A$113) | F5: =COUNTIF('Project Tracker'!$M$5:$M$113,"Completed") | H5: =COUNTIF('Project Tracker'!$M$5:$M$113,"In Progress") | J5: =COUNTIF('Project Tracker'!$M$5:$M$113,"Blocked") | L5: =COUNTIF('Project Tracker'!$M$5:$M$113,"At Risk") | P5: In Progress | Q5: =COUNTIF('Project Tracker'!$M$5:$M$113,P5)
P6: Completed | Q6: =COUNTIF('Project Tracker'!$M$5:$M$113,P6)
B7: Overall Progress % | D7: Hours Planned | F7: Hours Actual | H7: Budget Consumed | J7: Upcoming Milestones | L7: Overdue Dependencies | P7: At Risk | Q7: =COUNTIF('Project Tracker'!$M$5:$M$113,P7)
B8: =IFERROR(AVERAGE('Project Tracker'!$Q$5:$Q$113),0) | D8: =SUM('Project Tracker'!$R$5:$R$113) | F8: =SUM('Project Tracker'!$S$5:$S$113) | H8: =SUM('Project Tracker'!$U$5:$U$113) | J8: =COUNTIF(Milestones!$H$5:$H$27,"YES") | L8: =COUNTIF(Dependencies!$G$5:$G$200,"Overdue") | P8: Blocked | Q8: =COUNTIF('Project Tracker'!$M$5:$M$113,P8)
P11: Owner | Q11: Tasks
P12: Jawahar | Q12: =COUNTIF('Project Tracker'!$J$5:$J$113,P12)
P13: Kadarkarai | Q13: =COUNTIF('Project Tracker'!$J$5:$J$113,P13)
P14: MJ | Q14: =COUNTIF('Project Tracker'!$J$5:$J$113,P14)
P15: Shriguru | Q15: =COUNTIF('Project Tracker'!$J$5:$J$113,P15)
P16: Siva | Q16: =COUNTIF('Project Tracker'!$J$5:$J$113,P16)
P26: Month | Q26: Cumulative Completed % | R26: Planned Burn-up %
P27: 46204 | Q27: =IFERROR(COUNTIFS('Project Tracker'!$M$5:$M$113,"Completed",'Project Tracker'!$O$5:$O$113,"<="&EOMONTH(P27,0))/COUNTA('Project Tracker'!$A$5:$A$113),0) | R27: 0.083333333
P28: 46235 | Q28: =IFERROR(COUNTIFS('Project Tracker'!$M$5:$M$113,"Completed",'Project Tracker'!$O$5:$O$113,"<="&EOMONTH(P28,0))/COUNTA('Project Tracker'!$A$5:$A$113),0) | R28: 0.16666667
P29: 46266 | Q29: =IFERROR(COUNTIFS('Project Tracker'!$M$5:$M$113,"Completed",'Project Tracker'!$O$5:$O$113,"<="&EOMONTH(P29,0))/COUNTA('Project Tracker'!$A$5:$A$113),0) | R29: 0.25
P30: 46296 | Q30: =IFERROR(COUNTIFS('Project Tracker'!$M$5:$M$113,"Completed",'Project Tracker'!$O$5:$O$113,"<="&EOMONTH(P30,0))/COUNTA('Project Tracker'!$A$5:$A$113),0) | R30: 0.33333333
P31: 46327 | Q31: =IFERROR(COUNTIFS('Project Tracker'!$M$5:$M$113,"Completed",'Project Tracker'!$O$5:$O$113,"<="&EOMONTH(P31,0))/COUNTA('Project Tracker'!$A$5:$A$113),0) | R31: 0.41666667
P32: 46357 | Q32: =IFERROR(COUNTIFS('Project Tracker'!$M$5:$M$113,"Completed",'Project Tracker'!$O$5:$O$113,"<="&EOMONTH(P32,0))/COUNTA('Project Tracker'!$A$5:$A$113),0) | R32: 0.5
P33: 46388 | Q33: =IFERROR(COUNTIFS('Project Tracker'!$M$5:$M$113,"Completed",'Project Tracker'!$O$5:$O$113,"<="&EOMONTH(P33,0))/COUNTA('Project Tracker'!$A$5:$A$113),0) | R33: 0.58333333
P34: 46419 | Q34: =IFERROR(COUNTIFS('Project Tracker'!$M$5:$M$113,"Completed",'Project Tracker'!$O$5:$O$113,"<="&EOMONTH(P34,0))/COUNTA('Project Tracker'!$A$5:$A$113),0) | R34: 0.66666667
P35: 46447 | Q35: =IFERROR(COUNTIFS('Project Tracker'!$M$5:$M$113,"Completed",'Project Tracker'!$O$5:$O$113,"<="&EOMONTH(P35,0))/COUNTA('Project Tracker'!$A$5:$A$113),0) | R35: 0.75
P36: 46478 | Q36: =IFERROR(COUNTIFS('Project Tracker'!$M$5:$M$113,"Completed",'Project Tracker'!$O$5:$O$113,"<="&EOMONTH(P36,0))/COUNTA('Project Tracker'!$A$5:$A$113),0) | R36: 0.83333333
P37: 46508 | Q37: =IFERROR(COUNTIFS('Project Tracker'!$M$5:$M$113,"Completed",'Project Tracker'!$O$5:$O$113,"<="&EOMONTH(P37,0))/COUNTA('Project Tracker'!$A$5:$A$113),0) | R37: 0.91666667
P38: 46539 | Q38: =IFERROR(COUNTIFS('Project Tracker'!$M$5:$M$113,"Completed",'Project Tracker'!$O$5:$O$113,"<="&EOMONTH(P38,0))/COUNTA('Project Tracker'!$A$5:$A$113),0) | R38: 1
P42: Release | Q42: Avg % Complete
P43: R26.Q1 | Q43: =IFERROR(AVERAGEIF('Project Tracker'!$Z$5:$Z$113,P43,'Project Tracker'!$Q$5:$Q$113),0)
B44: Resource Utilization (see Resource Planning sheet for heatmap & detail) | P44: R26.Q2 | Q44: =IFERROR(AVERAGEIF('Project Tracker'!$Z$5:$Z$113,P44,'Project Tracker'!$Q$5:$Q$113),0)
B45: Avg Utilization | C45: =IFERROR(AVERAGE('Resource Planning'!$F$5:$F$9),0) | P45: R26.Q3 | Q45: =IFERROR(AVERAGEIF('Project Tracker'!$Z$5:$Z$113,P45,'Project Tracker'!$Q$5:$Q$113),0)
B46: Overallocated Resources | C46: =COUNTIF('Resource Planning'!$I$5:$I$9,"YES") | P46: R26.Q4 | Q46: =IFERROR(AVERAGEIF('Project Tracker'!$Z$5:$Z$113,P46,'Project Tracker'!$Q$5:$Q$113),0)
P47: R27.Q1 | Q47: =IFERROR(AVERAGEIF('Project Tracker'!$Z$5:$Z$113,P47,'Project Tracker'!$Q$5:$Q$113),0)
B48: LINE CHART — Progress trend uses Monthly Burn-up above. | P48: R27.Q2 | Q48: =IFERROR(AVERAGEIF('Project Tracker'!$Z$5:$Z$113,P48,'Project Tracker'!$Q$5:$Q$113),0)
P49: Hotfix | Q49: =IFERROR(AVERAGEIF('Project Tracker'!$Z$5:$Z$113,P49,'Project Tracker'!$Q$5:$Q$113),0)
B50: STATUS LEGEND | D50: HOW TO USE | P50: N/A | Q50: =IFERROR(AVERAGEIF('Project Tracker'!$Z$5:$Z$113,P50,'Project Tracker'!$Q$5:$Q$113),0)
B51: Completed | D51: 1. Update Project Tracker (status, dates, hours) — Dashboard KPIs refresh automatically.
B52: In Progress | D52: 2. Maintain dropdown values on Lookup Lists sheet (named ranges).
B53: At Risk | D53: 3. Review Gantt Chart weekly; orange ▶ marks current week.
B54: Blocked | D54: 4. Clear overdue Dependencies and High/Critical Risks in governance.
...

Sheet Project Tracker
A1: FY27 ENGINEERING PROJECT TRACKER
A2: Source: plan/FY 27 Draft Planning.xlsx · FY27 V1 | Plan window: 2026-07-01 → 2027-06-30 | Formula-driven | Weekly governance ready
A4: Task ID | B4: Epic | C4: Project | D4: Feature | E4: Sprint | F4: Phase | G4: Workstream | H4: Task Name | I4: Description | J4: Owner | K4: Team | L4: Priority | M4: Status | N4: Start Date | O4: End Date | P4: Duration | Q4: % Complete | R4: Planned Hours | S4: Actual Hours | T4: Variance | U4: Budget | V4: Dependency | W4: Blocked By | X4: Risk | Y4: Next Action | Z4: Target Release | AA4: Remarks | AB4: Critical Path
A5: T-001 | B5: CS 1.0 — Maintenance | C5: CS 1.0 | D5: Maintenance | E5: Sprint 01 | F5: Release | G5: Reliability | H5: Shutting down BRIKS service from Nackle | I5: Pending action to completely remove BRIKS services from Nackle ecosystem | J5: MJ | K5: Core Product | L5: High | M5: At Risk | N5: 46287 | O5: 46293 | P5: =IF(OR(N5="",O5=""),"",O5-N5+1) | Q5: 0.13 | R5: 40 | S5: 5.9 | T5: =S5-R5 | U5: 4400 | X5: R-19 | Y5: Clarify Include/Pending decision; rebaseline if needed | Z5: R26.Q1 | AA5: Include=Yes | Source=FY27 V1 | Timeline=Q1 FY27 | AB5: No
A6: T-002 | B6: CS 1.0 — Maintenance | C6: CS 1.0 | D6: Maintenance | E6: Sprint 02 | F6: Release | G6: Reliability | H6: Shutting Down Coupon/OTP Services | I6: Testing and Any support needed(Ensure all existing application 1X and 2.0 work as expected) | J6: MJ | K6: Core Product | L6: High | M6: In Progress | N6: 46213 | O6: 46226 | P6: =IF(OR(N6="",O6=""),"",O6-N6+1) | Q6: 0.36 | R6: 40 | S6: 14.6 | T6: =S6-R6 | U6: 4400 | V6: T-001 | Y6: Continue sprint commitments; demos Friday | Z6: R26.Q1 | AA6: Include=Yes | Source=FY27 V1 | Timeline=Q1 FY27 | Hours=TBD in source | AB6: No
A7: T-003 | B7: CS 1.0 — Funct Enhance | C7: CS 1.0 | D7: Funct Enhance | E7: Sprint 03 | F7: Design | G7: Product Delivery | H7: Integrate the email validation service for Channel Smart 1.0(Roshni to check) | I7: Handle the self registration and bulk load scneario | J7: MJ | K7: Core Product | L7: High | M7: In Progress | N7: 46236 | O7: 46242 | P7: =IF(OR(N7="",O7=""),"",O7-N7+1) | Q7: 0.36 | R7: 40 | S7: 14 | T7: =S7-R7 | U7: 4400 | V7: T-002 | Y7: Continue sprint commitments; demos Friday | Z7: R26.Q1 | AA7: Include=Yes | Source=FY27 V1 | Timeline=Q1 FY27 | AB7: No
A8: T-004 | B8: CS 1.0 — Funct Enhance | C8: CS 1.0 | D8: Funct Enhance | E8: Sprint 04 | F8: Design | G8: Product Delivery | H8: Build Unsubscribe feature for all the promotional emails(Roshni to check) | I8: Build Unsubscribe feature for all the promotional emails | J8: MJ | K8: Core Product | L8: High | M8: Not Started | N8: 46235 | O8: 46244 | P8: =IF(OR(N8="",O8=""),"",O8-N8+1) | Q8: 0 | R8: 60 | S8: 0 | T8: =S8-R8 | U8: 6600 | V8: T-003 | Y8: Confirm kickoff & acceptance criteria | Z8: R26.Q1 | AA8: Include=Yes | Source=FY27 V1 | Timeline=Q1 FY27 | AB8: No
A9: T-005 | B9: CS 1.0 — New Features | C9: CS 1.0 | D9: New Features | E9: Sprint 05 | F9: Build | G9: Product Delivery | H9: Cash + Wallet + Compliance - Integration patch for CS 1.0 | I9: Integrating the Cash/Wallet/Compliance to Existing 1.0 Customers | J9: MJ | K9: Core Product | L9: High | M9: Not Started | N9: 46235 | O9: 46267 | P9: =IF(OR(N9="",O9=""),"",O9-N9+1) | Q9: 0 | R9: 200 | S9: 0 | T9: =S9-R9 | U9: 22000 | V9: T-004 | Y9: Confirm kickoff & acceptance criteria | Z9: R26.Q1 | AA9: Include=Yes | Source=FY27 V1 | Timeline=July | AB9: No
A10: T-006 | B10: CS 2.0 — Funct Enhance | C10: CS 2.0 | D10: Funct Enhance | E10: Sprint 06 | F10: Design | G10: Product Delivery | H10: Build Pipeline for Achievo to be updated | J10: MJ | K10: Core Product | L10: High | M10: Not Started | N10: 46282 | O10: 46291 | P10: =IF(OR(N10="",O10=""),"",O10-N10+1) | Q10: 0 | R10: 40 | S10: 0 | T10: =S10-R10 | U10: 4400 | Y10: Confirm kickoff & acceptance criteria | Z10: R26.Q1 | AA10: Include=Yes | Source=FY27 V1 | Timeline=July | Hours=TBD in source | AB10: No
A11: T-007 | B11: CS 2.0 — Funct Enhance | C11: CS 2.0 | D11: Funct Enhance | E11: Sprint 01 | F11: Design | G11: Product Delivery | H11: Integrate the email validation service for Channel Smart 2.0(Roshni to check) | I11: Handle the self registration and bulk load scneario | J11: MJ | K11: Core Product | L11: High | M11: Not Started | N11: 46257 | O11: 46263 | P11: =IF(OR(N11="",O11=""),"",O11-N11+1) | Q11: 0 | R11: 40 | S11: 0 | T11: =S11-R11 | U11: 4400 | V11: T-006 | Y11: Confirm kickoff & acceptance criteria | Z11: R26.Q1 | AA11: Include=Yes | Source=FY27 V1 | Timeline=Q1 FY27 | AB11: No
A12: T-008 | B12: CS 2.0 — Funct Enhance | C12: CS 2.0 | D12: Funct Enhance | E12: Sprint 02 | F12: Design | G12: Product Delivery | H12: Build Unsubscribe feature for all the promotional emails(Roshni to check) | I12: Build Unsubscribe feature for all the promotional emails | J12: MJ | K12: Core Product | L12: High | M12: Not Started | N12: 46260 | O12: 46269 | P12: =IF(OR(N12="",O12=""),"",O12-N12+1) | Q12: 0 | R12: 60 | S12: 0 | T12: =S12-R12 | U12: 6600 | V12: T-007 | Y12: Confirm kickoff & acceptance criteria | Z12: R26.Q1 | AA12: Include=Yes | Source=FY27 V1 | Timeline=Q1 FY27 | AB12: No
A13: T-009 | B13: CS 2.0 — New Features | C13: CS 2.0 | D13: New Features | E13: Sprint 03 | F13: Build | G13: Product Delivery | H13: ERP Connerctor Service(Saleforce) | J13: MJ | K13: Core Product | L13: High | M13: Not Started | N13: 46204 | O13: 46261 | P13: =IF(OR(N13="",O13=""),"",O13-N13+1) | Q13: 0 | R13: 350 | S13: 0 | T13: =S13-R13 | U13: 38500 | V13: T-008 | Y13: Confirm kickoff & acceptance criteria | Z13: R26.Q1 | AA13: Include=Yes | Source=FY27 V1 | Timeline=Q1 FY27 | AB13: No
A14: T-010 | B14: CS 2.0 — Tech Maintenance | C14: CS 2.0 | D14: Tech Maintenance | E14: Sprint 04 | F14: Hypercare | G14: Reliability | H14: Technology refresh | I14: Mandatory adoption of newer tools and frameworks Phoenix - Platform Site Upgrades (Onetime) To 16.x Admin - Platform Site Upgrades (Onetime) To 16.x | J14: Jawahar | K14: Core Product | L14: High | M14: In Progress | N14: 46265 | O14: 46277 | P14: =IF(OR(N14="",O14=""),"",O14-N14+1) | Q14: 0.29 | R14: 80 | S14: 26.3 | T14: =S14-R14 | U14: 8800 | V14: T-009 | Y14: Continue sprint commitments; demos Friday | Z14: R26.Q1 | AA14: Include=Yes | Source=FY27 V1 | Timeline=Q1 FY27 | AB14: No
A15: T-011 | B15: CS 2.0 — Tech Maintenance | C15: CS 2.0 | D15: Tech Maintenance | E15: Sprint 05 | F15: Hypercare | G15: Reliability | H15: Fix for Critical Performance Issue(Claims, File Upload) | I15: Top 10 recommendations and Performance Fix to be applied for the existing high priority issues. | J15: Jawahar | K15: Core Product | L15: High | M15: In Progress | N15: 46271 | O15: 46284 | P15: =IF(OR(N15="",O15=""),"",O15-N15+1) | Q15: 0.22 | R15: 40 | S15: 9.5 | T15: =S15-R15 | U15: 4400 | V15: T-010 | Y15: Continue sprint commitments; demos Friday | Z15: R26.Q1 | AA15: Include=Yes | Source=FY27 V1 | Timeline=July | Hours=TBD in source | AB15: No
A16: T-012 | B16: CS 2.0 — New Features | C16: CS 2.0 | D16: New Features | E16: Sprint 06 | F16: Build | G16: Product Delivery | H16: Build a game engine - Requirements | I16: N/A | J16: MJ | K16: Core Product | L16: High | M16: Not Started | N16: 46208 | O16: 46217 | P16: =IF(OR(N16="",O16=""),"",O16-N16+1) | Q16: 0 | R16: 60 | S16: 0 | T16: =S16-R16 | U16: 6600 | V16: T-011 | Y16: Confirm kickoff & acceptance criteria | Z16: R26.Q1 | AA16: Include=Yes | Source=FY27 V1 | Timeline=Q1 FY27 | AB16: No
A17: T-013 | B17: CS 2.0 — New Features | C17: CS 2.0 | D17: New Features | E17: Sprint 01 | F17: Build | G17: Product Delivery | H17: BRD Composer | I17: BRD Composer | J17: MJ | K17: Core Product | L17: High | M17: In Progress | N17: 46237 | O17: 46286 | P17: =IF(OR(N17="",O17=""),"",O17-N17+1) | Q17: 0.24 | R17: 300 | S17: 76.5 | T17: =S17-R17 | U17: 33000 | V17: T-012 | Y17: Continue sprint commitments; demos Friday | Z17: R26.Q1 | AA17: Include=Yes | Source=FY27 V1 | Timeline=Q1 FY27 | AB17: No
A18: T-014 | B18: CS 2.0 — New Features | C18: CS 2.0 | D18: New Features | E18: Sprint 02 | F18: Build | G18: Product Delivery | H18: Communication connector which can support the Whatsapp and Wechat communicaton bi direction | J18: MJ | K18: Core Product | L18: High | M18: Not Started | N18: 46212 | O18: 46281 | P18: =IF(OR(N18="",O18=""),"",O18-N18+1) | Q18: 0 | R18: 600 | S18: 0 | T18: =S18-R18 | U18: 66000 | V18: T-013 | Y18: Confirm kickoff & acceptance criteria | Z18: R26.Q1 | AA18: Include=Yes | Source=FY27 V1 | Timeline=Q1 FY27 | AB18: No
A19: T-015 | B19: CS 2.0 — New Features | C19: CS 2.0 | D19: New Features | E19: Sprint 13 | F19: Build | G19: Product Delivery | H19: AI-Powered Claim Validation | I19: Introduce AI-assisted claim validation capabilities leveraging intelligent document processing to automate claim ingestion, extraction, validation, routing, and continuous learning. Strategic FY27 initiative under evaluation. | J19: MJ | K19: Core Product | L19: High | M19: Not Started | N19: 46410 | O19: 46419 | P19: =IF(OR(N19="",O19=""),"",O19-N19+1) | Q19: 0 | R19: 40 | S19: 0 | T19: =S19-R19 | U19: 4400 | Y19: Confirm kickoff & acceptance criteria | Z19: R27.Q1 | AA19: Include=Yes | Source=FY27 V1 | Timeline=Q3 FY27 | Hours=TBD in source | AB19: No
A20: T-016 | B20: CS 2.0 — New Features | C20: CS 2.0 | D20: New Features | E20: Sprint 22 | F20: Build | G20: Product Delivery | H20: MDF Budget Management & Incentivization | I20: Develop end-to-end MDF request, approval, budget allocation, campaign setup, and incentive distribution capabilities to improve fund utilization and business outcome tracking. Strategic FY27 initiative under evaluation. | J20: MJ | K20: Core Product | L20: High | M20: At Risk | N20: 46535 | O20: 46544 | P20: =IF(OR(N20="",O20=""),"",O20-N20+1) | Q20: 0.09 | R20: 40 | S20: 3.4 | T20: =S20-R20 | U20: 4400 | V20: T-015 | X20: R-14 | Y20: Clarify Include/Pending decision; rebaseline if needed | Z20: N/A | AA20: Include=Pending | Source=FY27 V1 | Timeline=TBD FY27 | Hours=TBD in source | AB20: No
A21: T-017 | B21: CS 2.0 — New Features | C21: CS 2.0 | D21: New Features | E21: Sprint 23 | F21: Build | G21: Product Delivery | H21: AI Display Audit & Compliance Management | I21: Implement AI-powered image analysis to automate display compliance audits, validate merchandising standards, and improve audit scalability, accuracy, and efficiency. Strategic FY27 initiative under evaluation. | J21: MJ | K21: Core Product | L21: High | M21: Blocked | N21: 46482 | O21: 46509 | P21: =IF(OR(N21="",O21=""),"",O21-N21+1) | Q21: 0.14 | R21: 40 | S21: 5.6 | T21: =S21-R21 | U21: 4400 | V21: T-016 | W21: T-016 | X21: R-20 | Y21: Resolve blocker with dependency owner | Z21: N/A | AA21: Include=Pending | Source=FY27 V1 | Timeline=TBD FY27 | Hours=TBD in source | AB21: No
A22: T-018 | B22: CS 2.0 — New Features | C22: CS 2.0 | D22: New Features | E22: Sprint 24 | F22: Build | G22: Product Delivery | H22: Organization-Centric Loyalty Journey | I22: Enable partner organizations to participate in loyalty and incentive programs through organization onboarding, governance controls, centralized reward management, and organization-led participation models. Strategic FY27 initiative under evaluation. | J22: MJ | K22: Core Product | L22: High | M22: At Risk | N22: 46500 | O22: 46527 | P22: =IF(OR(N22="",O22=""),"",O22-N22+1) | Q22: 0.05 | R22: 40 | S22: 1.9 | T22: =S22-R22 | U22: 4400 | V22: T-017 | X22: R-09 | Y22: Clarify Include/Pending decision; rebaseline if needed | Z22: N/A | AA22: Include=Pending | Source=FY27 V1 | Timeline=TBD FY27 | Hours=TBD in source | AB22: No
A23: T-019 | B23: CS 2.0 — New Features | C23: CS 2.0 | D23: New Features | E23: Sprint 25 | F23: Build | G23: Product Delivery | H23: Social Advocacy & Partner Influence Platform | I23: Enable partners to share approved brand content, track engagement and attribution, and participate in incentive-driven advocacy programs that extend brand reach and influence. Strategic FY27 initiative under evaluation. | J23: MJ | K23: Core Product | L23: High | M23: At Risk | N23: 46500 | O23: 46520 | P23: =IF(OR(N23="",O23=""),"",O23-N23+1) | Q23: 0.2 | R23: 40 | S23: 7.7 | T23: =S23-R23 | U23: 4400 | V23: T-018 | X23: R-09 | Y23: Clarify Include/Pending decision; rebaseline if needed | Z23: N/A | AA23: Include=Pending | Source=FY27 V1 | Timeline=TBD FY27 | Hours=TBD in source | AB23: No
A24: T-020 | B24: CS 2.0 — New Features | C24: CS 2.0 | D24: New Features | E24: Sprint 26 | F24: Build | G24: Product Delivery | H24: Partner Referral & Growth Engine | I24: Establish a referral ecosystem with attribution tracking, milestone-based rewards, referral analytics, and conversion visibility to support partner-led acquisition and network-driven growth. Strategic FY27 initiative under evaluation. | J24: MJ | K24: Core Product | L24: High | M24: At Risk | N24: 46544 | O24: 46553 | P24: =IF(OR(N24="",O24=""),"",O24-N24+1) | Q24: 0.12 | R24: 40 | S24: 4.3 | T24: =S24-R24 | U24: 4400 | V24: T-019 | X24: R-18 | Y24: Clarify Include/Pending decision; rebaseline if needed | Z24: N/A | AA24: Include=Pending | Source=FY27 V1 | Timeline=TBD FY27 | Hours=TBD in source | AB24: No
A25: T-021 | B25: CS 2.0 — New Features | C25: CS 2.0 | D25: New Features | E25: Sprint 26 | F25: Build | G25: Product Delivery | H25: AI-Powered Audience Segmentation | I25: Enable business users to create audience segments using natural language queries across transactional, behavioral, and engagement data, improving campaign targeting and intervention effectiveness. Strategic FY27 initiative under evaluation. | J25: MJ | K25: Core Product | L25: High | M25: At Risk | N25: 46513 | O25: 46540 | P25: =IF(OR(N25="",O25=""),"",O25-N25+1) | Q25: 0.07 | R25: 40 | S25: 2.7 | T25: =S25-R25 | U25: 4400 | V25: T-020 | X25: R-02 | Y25: Clarify Include/Pending decision; rebaseline if needed | Z25: N/A | AA25: Include=Pending | Source=FY27 V1 | Timeline=TBD FY27 | Hours=TBD in source | AB25: No
A26: T-022 | B26: CS 2.0 — New Features | C26: CS 2.0 | D26: New Features | E26: Sprint 22 | F26: Build | G26: Product Delivery | H26: Embedded Gamification Experiences | I26: Introduce contextual, embedded gaming experiences within partner journeys to increase engagement, accelerate reward cycles, encourage repeat interactions, and improve program participation. Strategic FY27 initiative under evaluation. | J26: MJ | K26: Core Product | L26: High | M26: At Risk | N26: 46528 | O26: 46537 | P26: =IF(OR(N26="",O26=""),"",O26-N26+1) | Q26: 0.15 | R26: 40 | S26: 6.2 | T26: =S26-R26 | U26: 4400 | V26: T-021 | X26: R-06 | Y26: Clarify Include/Pending decision; rebaseline if needed | Z26: N/A | AA26: Include=Pending | Source=FY27 V1 | Timeline=TBD FY27 | Hours=TBD in source | AB26: No
A27: T-023 | B27: CS 2.0 Achievo — Funct Enhance | C27: CS 2.0 Achievo | D27: Funct Enhance | E27: Sprint 03 | F27: Design | G27: Product Delivery | H27: Achievo - UI/UX Improvements | I27: UI/UX improvements based on External recommendations | J27: Shriguru | K27: Rewards | L27: Critical | M27: Not Started | N27: 46236 | O27: 46256 | P27: =IF(OR(N27="",O27=""),"",O27-N27+1) | Q27: 0 | R27: 40 | S27: 0 | T27: =S27-R27 | U27: 4400 | Y27: Confirm kickoff & acceptance criteria | Z27: R26.Q1 | AA27: Include=Yes | Source=FY27 V1 | Timeline=Q1 FY27 | Hours=TBD in source | AB27: No
A28: T-024 | B28: CS 2.0 Achievo — Tech Maintenance | C28: CS 2.0 Achievo | D28: Tech Maintenance | E28: Sprint 04 | F28: Hypercare | G28: Reliability | H28: Achievo - Mobile Performance Improvement.(Analysis) | I28: Overall Mobile Performance Recommendations | J28: Shriguru | K28: Rewards | L28: Critical | M28: In Progress | N28: 46214 | O28: 46218 | P28: =IF(OR(N28="",O28=""),"",O28-N28+1) | Q28: 0.29 | R28: 24 | S28: 6.5 | T28: =S28-R28 | U28: 2640 | V28: T-023 | Y28: Continue sprint commitments; demos Friday | Z28: R26.Q1 | AA28: Include=Yes | Source=FY27 V1 | Timeline=Q1 FY27 | AB28: Yes
A29: T-025 | B29: CS 2.0 Achievo — Tech Maintenance | C29: CS 2.0 Achievo | D29: Tech Maintenance | E29: Sprint 05 | F29: Hypercare | G29: Reliability | H29: Achievo - Mobile Performance Improvement.(Implementation) | I29: Overall Mobile Performance Improvements | J29: Shriguru | K29: Rewards | L29: Critical | M29: In Progress | N29: 46278 | O29: 46287 | P29: =IF(OR(N29="",O29=""),"",O29-N29+1) | Q29: 0.24 | R29: 40 | S29: 8.8 | T29: =S29-R29 | U29: 4400 | V29: T-024 | Y29: Continue sprint commitments; demos Friday | Z29: R26.Q1 | AA29: Include=Yes | Source=FY27 V1 | Timeline=Q1 FY27 | Hours=TBD in source | AB29: Yes
A30: T-026 | B30: CS 2.0 Achievo — Tech Maintenance | C30: CS 2.0 Achievo | D30: Tech Maintenance | E30: Sprint 06 | F30: Hypercare | G30: Reliability | H30: Achievo - Android 16 Upgrade | I30: Achievo - Android 16 Upgrade. | J30: Shriguru | K30: Rewards | L30: High | M30: Not Started | N30: 46265 | O30: 46271 | P30: =IF(OR(N30="",O30=""),"",O30-N30+1) | Q30: 0 | R30: 40 | S30: 0 | T30: =S30-R30 | U30: 4400 | V30: T-025 | Y30: Confirm kickoff & acceptance criteria | Z30: R26.Q1 | AA30: Include=Yes | Source=FY27 V1 | Timeline=Q1 FY27 | AB30: No
A31: T-027 | B31: CS 2.0 Achievo — Tech Maintenance | C31: CS 2.0 Achievo | D31: Tech Maintenance | E31: Sprint 01 | F31: Hypercare | G31: Reliability | H31: Achievo - iOS Updates | I31: N/A | J31: Shriguru | K31: Rewards | L31: High | M31: In Progress | N31: 46219 | O31: 46225 | P31: =IF(OR(N31="",O31=""),"",O31-N31+1) | Q31: 0.11 | R31: 40 | S31: 4.2 | T31: =S31-R31 | U31: 4400 | V31: T-026 | Y31: Continue sprint commitments; demos Friday | Z31: R26.Q1 | AA31: Include=Yes | Source=FY27 V1 | Timeline=Q1 FY27 | AB31: No
A32: T-028 | B32: CS 2.0 Achievo — New Features | C32: CS 2.0 Achievo | D32: New Features | E32: Sprint 23 | F32: Build | G32: Product Delivery | H32: Achievo Mobile Experience Modernization | I32: Modernize Achievo with mobile-native capabilities including push notifications, voice-assisted discovery, enhanced UX, QR-enabled interactions, gamification, and AI-assisted workflows to increase engagement and participation. Strategic FY27 initiative under evaluation. | J32: Shriguru | K32: Rewards | L32: High | M32: At Risk | N32: 46515 | O32: 46528 | P32: =IF(OR(N32="",O32=""),"",O32-N32+1) | Q32: 0.24 | R32: 40 | S32: 10.6 | T32: =S32-R32 | U32: 4400 | V32: T-027 | X32: R-04 | Y32: Clarify Include/Pending decision; rebaseline if needed | Z32: N/A | AA32: Include=Pending | Source=FY27 V1 | Timeline=TBD FY27 | Hours=TBD in source | AB32: No
A33: T-029 | B33: CS 2.0 — Funct Enhance | C33: CS 2.0 | D33: Funct Enhance | E33: Sprint 24 | F33: Design | G33: Product Delivery | H33: Existing Product Backlog and Delivery Priority Items as needed to be added to Core Product | I33: Need to work with Roshni to identify Priority items to be taken into Core | J33: MJ | K33: Core Product | L33: High | M33: Blocked | N33: 46549 | O33: 46558 | P33: =IF(OR(N33="",O33=""),"",O33-N33+1) | Q33: 0.15 | R33: 40 | S33: 6 | T33: =S33-R33 | U33: 4400 | V33: T-022 | W33: T-022 | X33: R-03 | Y33: Resolve blocker with dependency owner | Z33: N/A | AA33: Include=Pending | Source=FY27 V1 | Timeline=TBD FY27 | Hours=TBD in source | AB33: No
A34: T-030 | B34: CS 2.0 Core — Tech Enhance | C34: CS 2.0 Core | D34: Tech Enhance | E34: Sprint 02 | F34: Build | G34: Platform | H34: New UI for platform portal | J34: MJ | K34: Platform | L34: High | M34: Not Started | N34: 46262 | O34: 46288 | P34: =IF(OR(N34="",O34=""),"",O34-N34+1) | Q34: 0 | R34: 160 | S34: 0 | T34: =S34-R34 | U34: 17600 | Y34: Confirm kickoff & acceptance criteria | Z34: R26.Q1 | AA34: Include=Yes | Source=FY27 V1 | Timeline=Q1 FY27 | AB34: No
A35: T-031 | B35: CS 2.0 Core — Tech Enhance | C35: CS 2.0 Core | D35: Tech Enhance | E35: Sprint 03 | F35: Build | G35: Product Delivery | H35: Architecture Proposal: Core + Extension Model for Participant Portals | I35: Define a Core + Extension architecture model for Participant Portals to separate common product capabilities from client-specific customizations. This will help reduce the effort required to apply latest product changes across multiple delivery deployments, minimize the risk of overriding existing client-specific features, and improve maintainability, upgradeability, and release consistency across implementations. | J35: MJ | K35: Platform | L35: Critical | M35: Not Started | N35: 46209 | O35: 46278 | P35: =IF(OR(N35="",O35=""),"",O35-N35+1) | Q35: 0 | R35: 600 | S35: 0 | T35: =S35-R35 | U35: 66000 | V35: T-030 | Y35: Confirm kickoff & acceptance criteria | Z35: R26.Q1 | AA35: Include=Yes | Source=FY27 V1 | Timeline=July | AB35: No
A36: T-032 | B36: CS 2.0 Core — Tech Enhance | C36: CS 2.0 Core | D36: Tech Enhance | E36: Sprint 04 | F36: Build | G36: Product Delivery | H36: File Upload Module Stabilization and Validation Enhancements (Check if it can be moved to Q2) | I36: Enhance the existing File Upload Module with improved validation, tracking, retry handling, and stabilization capabilities. This will improve upload reliability, reduce processing failures, provide better visibility into upload status, support controlled reprocessing, and strengthen the overall stability of file-based data ingestion. | J36: MJ | K36: Platform | L36: Critical | M36: Not Started | N36: 46215 | O36: 46284 | P36: =IF(OR(N36="",O36=""),"",O36-N36+1) | Q36: 0 | R36: 600 | S36: 0 | T36: =S36-R36 | U36: 66000 | V36: T-031 | Y36: Confirm kickoff & acceptance criteria | Z36: R26.Q1 | AA36: Include=Yes | Source=FY27 V1 | Timeline=July | AB36: No
A37: T-033 | B37: CS 2.0 Core — Tech Maintenance | C37: CS 2.0 Core | D37: Tech Maintenance | E37: Sprint 05 | F37: Hypercare | G37: Reliability | H37: Release Governance, Code Merge and Deployment Control | I37: Standardize the code merge and release management process by improving version control, conflict handling, release planning, approvals, deployment tracking, rollback governance, and client-specific patch management. This will strengthen engineering governance, reduce release risks, and improve operational control across releases. | J37: Jawahar | K37: Platform | L37: High | M37: In Progress | N37: 46243 | O37: 46279 | P37: =IF(OR(N37="",O37=""),"",O37-N37+1) | Q37: 0.22 | R37: 220 | S37: 43.9 | T37: =S37-R37 | U37: 24200 | V37: T-032 | Y37: Continue sprint commitments; demos Friday | Z37: R26.Q1 | AA37: Include=Yes | Source=FY27 V1 | Timeline=Q1 FY27 | AB37: No
A38: T-034 | B38: CS 2.0 Core — Tech Maintenance | C38: CS 2.0 Core | D38: Tech Maintenance | E38: Sprint 06 | F38: Hypercare | G38: Reliability | H38: Achievo Mobile App Upgrades and Store Policy Compliance Updates | I38: Perform Achievo mobile app upgrades and store-specific policy updates for iOS and Android. This includes updating SDKs, dependencies, build tools, privacy/permission declarations, App Store and Play Store compliance requirements, testing, build validation, and supporting app submission/review activities. | J38: Jawahar | K38: Platform | L38: Critical | M38: Not Started | N38: 46225 | O38: 46277 | P38: =IF(OR(N38="",O38=""),"",O38-N38+1) | Q38: 0 | R38: 320 | S38: 0 | T38: =S38-R38 | U38: 35200 | V38: T-033 | Y38: Confirm kickoff & acceptance criteria | Z38: R26.Q1 | AA38: Include=Yes | Source=FY27 V1 | Timeline=Q1 FY27 | AB38: No
A39: T-035 | B39: CS 2.0 Core — Tech Maintenance | C39: CS 2.0 Core | D39: Tech Maintenance | E39: Sprint 01 | F39: Hypercare | G39: Reliability | H39: Next.js 16.x LTS Upgrade for Admin Console and Platform Web Apps | I39: Upgrade Next.js to Version 16.x LTS (Admin & Platform) - 14.X is already outdated and 15.x is reaching end of life by 21/Oct/2026 | J39: Jawahar | K39: Platform | L39: Critical | M39: Not Started | N39: 46256 | O39: 46292 | P39: =IF(OR(N39="",O39=""),"",O39-N39+1) | Q39: 0 | R39: 220 | S39: 0 | T39: =S39-R39 | U39: 24200 | V39: T-034 | Y39: Confirm kickoff & acceptance criteria | Z39: R26.Q1 | AA39: Include=Yes | Source=FY27 V1 | Timeline=July | AB39: No
A40: T-036 | B40: CS 2.0 Core — Tech Enhance | C40: CS 2.0 Core | D40: Tech Enhance | E40: Sprint 02 | F40: Build | G40: Platform | H40: Scalable File Upload Processing Enhancement | I40: Enhance the existing file upload processing architecture to handle large files with more than 100,000 records. This will address the current single-pod stateful processing limitation by improving scalability, reliability, and fault tolerance for high-volume uploads | J40: MJ | K40: Platform | L40: Critical | M40: Not Started | N40: 46226 | O40: 46255 | P40: =IF(OR(N40="",O40=""),"",O40-N40+1) | Q40: 0 | R40: 180 | S40: 0 | T40: =S40-R40 | U40: 19800 | V40: T-035 | Y40: Confirm kickoff & acceptance criteria | Z40: R26.Q1 | AA40: Include=Yes | Source=FY27 V1 | Timeline=Q1 FY27 | AB40: No
A41: T-037 | B41: CS 2.0 Core — Tech Enhance | C41: CS 2.0 Core | D41: Tech Enhance | E41: Sprint 03 | F41: Build | G41: Product Delivery | H41: AWS Secrets Manager Enforcement for Service Credentials | I41: Enforce AWS Secrets Manager usage for all service credentials and remove any plain-text or insecure storage of credentials from configuration files, environment variables, deployment scripts, and service-level settings. This will improve credential security, strengthen governance, reduce secret exposure risk, and align services with secure configuration management practices. | J41: MJ | K41: Platform | L41: Critical | M41: In Progress | N41: 46209 | O41: 46235 | P41: =IF(OR(N41="",O41=""),"",O41-N41+1) | Q41: 0.42 | R41: 160 | S41: 58.7 | T41: =S41-R41 | U41: 17600 | V41: T-036 | X41: R-01 | Y41: Continue sprint commitments; demos Friday | Z41: R26.Q1 | AA41: Include=Yes | Source=FY27 V1 | Timeline=Q1 FY27 | AB41: Yes
...

Sheet Gantt Chart
A1: GANTT CHART — FY27 (Weekly / Monthly / Quarterly)
A2: Bars auto-highlight from Start/End. Legend: Green=Completed · Blue=In Progress · Yellow=At Risk · Red=Blocked/Critical · Grey=Not Started · ◆=Milestone week · Orange header=Current week
I3: =IF(AND(TODAY()>=I$4,TODAY()<I$4+7),"▶","") | J3: =IF(AND(TODAY()>=J$4,TODAY()<J$4+7),"▶","") | K3: =IF(AND(TODAY()>=K$4,TODAY()<K$4+7),"▶","") | L3: =IF(AND(TODAY()>=L$4,TODAY()<L$4+7),"▶","") | M3: =IF(AND(TODAY()>=M$4,TODAY()<M$4+7),"▶","") | N3: =IF(AND(TODAY()>=N$4,TODAY()<N$4+7),"▶","") | O3: =IF(AND(TODAY()>=O$4,TODAY()<O$4+7),"▶","") | P3: =IF(AND(TODAY()>=P$4,TODAY()<P$4+7),"▶","") | ... BI3: =IF(AND(TODAY()>=BI$4,TODAY()<BI$4+7),"▶","")
A4: Task ID | B4: Task Name | C4: Owner | D4: Status | E4: Start | F4: End | G4: % Complete | H4: Critical | I4: 46202 | J4: 46209 | K4: 46216 | L4: 46223 | M4: 46230 | N4: 46237 | O4: 46244 | P4: 46251 | Q4: 46258 | R4: 46265 | S4: 46272 | T4: 46279 | U4: 46286 | V4: 46293 | W4: 46300 | X4: 46307 | Y4: 46314 | Z4: 46321 | AA4: 46328 | AB4: 46335 | AC4: 46342 | AD4: 46349 | AE4: 46356 | AF4: 46363 | AG4: 46370 | AH4: 46377 | AI4: 46384 | AJ4: 46391 | AK4: 46398 | AL4: 46405 | AM4: 46412 | AN4: 46419 | AO4: 46426 | AP4: 46433 | AQ4: 46440 | AR4: 46447 | AS4: 46454 | AT4: 46461 | AU4: 46468 | AV4: 46475 | AW4: 46482 | AX4: 46489 | AY4: 46496 | AZ4: 46503 | BA4: 46510 | BB4: 46517 | BC4: 46524 | BD4: 46531 | BE4: 46538 | BF4: 46545 | BG4: 46552 | BH4: 46559 | BI4: 46566
A5: T-001 | B5: Shutting down BRIKS service from Nackle | C5: MJ | D5: At Risk | E5: 46287 | F5: 46293 | G5: 0.13 | H5: No | I5: =IF(OR($E5="",$F5=""),"",IF(AND(I$4<=$F5,I$4+6>=$E5),IF($F5-$E5<=2,"◆",IF($H5="Yes","X",LEFT($D5,1))),"")) | J5: =IF(OR($E5="",$F5=""),"",IF(AND(J$4<=$F5,J$4+6>=$E5),IF($F5-$E5<=2,"◆",IF($H5="Yes","X",LEFT($D5,1))),"")) | K5: =IF(OR($E5="",$F5=""),"",IF(AND(K$4<=$F5,K$4+6>=$E5),IF($F5-$E5<=2,"◆",IF($H5="Yes","X",LEFT($D5,1))),"")) | L5: =IF(OR($E5="",$F5=""),"",IF(AND(L$4<=$F5,L$4+6>=$E5),IF($F5-$E5<=2,"◆",IF($H5="Yes","X",LEFT($D5,1))),"")) | M5: =IF(OR($E5="",$F5=""),"",IF(AND(M$4<=$F5,M$4+6>=$E5),IF($F5-$E5<=2,"◆",IF($H5="Yes","X",LEFT($D5,1))),"")) | N5: =IF(OR($E5="",$F5=""),"",IF(AND(N$4<=$F5,N$4+6>=$E5),IF($F5-$E5<=2,"◆",IF($H5="Yes","X",LEFT($D5,1))),"")) | O5: =IF(OR($E5="",$F5=""),"",IF(AND(O$4<=$F5,O$4+6>=$E5),IF($F5-$E5<=2,"◆",IF($H5="Yes","X",LEFT($D5,1))),"")) | P5: =IF(OR($E5="",$F5=""),"",IF(AND(P$4<=$F5,P$4+6>=$E5),IF($F5-$E5<=2,"◆",IF($H5="Yes","X",LEFT($D5,1))),"")) | ... BI5: =IF(OR($E5="",$F5=""),"",IF(AND(BI$4<=$F5,BI$4+6>=$E5),IF($F5-$E5<=2,"◆",IF($H5="Yes","X",LEFT($D5,1))),""))
A6: T-002 | B6: Shutting Down Coupon/OTP Services | C6: MJ | D6: In Progress | E6: 46213 | F6: 46226 | G6: 0.36 | H6: No | I6: =IF(OR($E6="",$F6=""),"",IF(AND(I$4<=$F6,I$4+6>=$E6),IF($F6-$E6<=2,"◆",IF($H6="Yes","X",LEFT($D6,1))),"")) | J6: =IF(OR($E6="",$F6=""),"",IF(AND(J$4<=$F6,J$4+6>=$E6),IF($F6-$E6<=2,"◆",IF($H6="Yes","X",LEFT($D6,1))),"")) | K6: =IF(OR($E6="",$F6=""),"",IF(AND(K$4<=$F6,K$4+6>=$E6),IF($F6-$E6<=2,"◆",IF($H6="Yes","X",LEFT($D6,1))),"")) | L6: =IF(OR($E6="",$F6=""),"",IF(AND(L$4<=$F6,L$4+6>=$E6),IF($F6-$E6<=2,"◆",IF($H6="Yes","X",LEFT($D6,1))),"")) | M6: =IF(OR($E6="",$F6=""),"",IF(AND(M$4<=$F6,M$4+6>=$E6),IF($F6-$E6<=2,"◆",IF($H6="Yes","X",LEFT($D6,1))),"")) | N6: =IF(OR($E6="",$F6=""),"",IF(AND(N$4<=$F6,N$4+6>=$E6),IF($F6-$E6<=2,"◆",IF($H6="Yes","X",LEFT($D6,1))),"")) | O6: =IF(OR($E6="",$F6=""),"",IF(AND(O$4<=$F6,O$4+6>=$E6),IF($F6-$E6<=2,"◆",IF($H6="Yes","X",LEFT($D6,1))),"")) | P6: =IF(OR($E6="",$F6=""),"",IF(AND(P$4<=$F6,P$4+6>=$E6),IF($F6-$E6<=2,"◆",IF($H6="Yes","X",LEFT($D6,1))),"")) | ... BI6: =IF(OR($E6="",$F6=""),"",IF(AND(BI$4<=$F6,BI$4+6>=$E6),IF($F6-$E6<=2,"◆",IF($H6="Yes","X",LEFT($D6,1))),""))
A7: T-003 | B7: Integrate the email validation service for Channel Smart 1.0(Roshni to check) | C7: MJ | D7: In Progress | E7: 46236 | F7: 46242 | G7: 0.36 | H7: No | I7: =IF(OR($E7="",$F7=""),"",IF(AND(I$4<=$F7,I$4+6>=$E7),IF($F7-$E7<=2,"◆",IF($H7="Yes","X",LEFT($D7,1))),"")) | J7: =IF(OR($E7="",$F7=""),"",IF(AND(J$4<=$F7,J$4+6>=$E7),IF($F7-$E7<=2,"◆",IF($H7="Yes","X",LEFT($D7,1))),"")) | K7: =IF(OR($E7="",$F7=""),"",IF(AND(K$4<=$F7,K$4+6>=$E7),IF($F7-$E7<=2,"◆",IF($H7="Yes","X",LEFT($D7,1))),"")) | L7: =IF(OR($E7="",$F7=""),"",IF(AND(L$4<=$F7,L$4+6>=$E7),IF($F7-$E7<=2,"◆",IF($H7="Yes","X",LEFT($D7,1))),"")) | M7: =IF(OR($E7="",$F7=""),"",IF(AND(M$4<=$F7,M$4+6>=$E7),IF($F7-$E7<=2,"◆",IF($H7="Yes","X",LEFT($D7,1))),"")) | N7: =IF(OR($E7="",$F7=""),"",IF(AND(N$4<=$F7,N$4+6>=$E7),IF($F7-$E7<=2,"◆",IF($H7="Yes","X",LEFT($D7,1))),"")) | O7: =IF(OR($E7="",$F7=""),"",IF(AND(O$4<=$F7,O$4+6>=$E7),IF($F7-$E7<=2,"◆",IF($H7="Yes","X",LEFT($D7,1))),"")) | P7: =IF(OR($E7="",$F7=""),"",IF(AND(P$4<=$F7,P$4+6>=$E7),IF($F7-$E7<=2,"◆",IF($H7="Yes","X",LEFT($D7,1))),"")) | ... BI7: =IF(OR($E7="",$F7=""),"",IF(AND(BI$4<=$F7,BI$4+6>=$E7),IF($F7-$E7<=2,"◆",IF($H7="Yes","X",LEFT($D7,1))),""))
A8: T-004 | B8: Build Unsubscribe feature for all the promotional emails(Roshni to check) | C8: MJ | D8: Not Started | E8: 46235 | F8: 46244 | G8: 0 | H8: No | I8: =IF(OR($E8="",$F8=""),"",IF(AND(I$4<=$F8,I$4+6>=$E8),IF($F8-$E8<=2,"◆",IF($H8="Yes","X",LEFT($D8,1))),"")) | J8: =IF(OR($E8="",$F8=""),"",IF(AND(J$4<=$F8,J$4+6>=$E8),IF($F8-$E8<=2,"◆",IF($H8="Yes","X",LEFT($D8,1))),"")) | K8: =IF(OR($E8="",$F8=""),"",IF(AND(K$4<=$F8,K$4+6>=$E8),IF($F8-$E8<=2,"◆",IF($H8="Yes","X",LEFT($D8,1))),"")) | L8: =IF(OR($E8="",$F8=""),"",IF(AND(L$4<=$F8,L$4+6>=$E8),IF($F8-$E8<=2,"◆",IF($H8="Yes","X",LEFT($D8,1))),"")) | M8: =IF(OR($E8="",$F8=""),"",IF(AND(M$4<=$F8,M$4+6>=$E8),IF($F8-$E8<=2,"◆",IF($H8="Yes","X",LEFT($D8,1))),"")) | N8: =IF(OR($E8="",$F8=""),"",IF(AND(N$4<=$F8,N$4+6>=$E8),IF($F8-$E8<=2,"◆",IF($H8="Yes","X",LEFT($D8,1))),"")) | O8: =IF(OR($E8="",$F8=""),"",IF(AND(O$4<=$F8,O$4+6>=$E8),IF($F8-$E8<=2,"◆",IF($H8="Yes","X",LEFT($D8,1))),"")) | P8: =IF(OR($E8="",$F8=""),"",IF(AND(P$4<=$F8,P$4+6>=$E8),IF($F8-$E8<=2,"◆",IF($H8="Yes","X",LEFT($D8,1))),"")) | ... BI8: =IF(OR($E8="",$F8=""),"",IF(AND(BI$4<=$F8,BI$4+6>=$E8),IF($F8-$E8<=2,"◆",IF($H8="Yes","X",LEFT($D8,1))),""))
A9: T-005 | B9: Cash + Wallet + Compliance - Integration patch for CS 1.0 | C9: MJ | D9: Not Started | E9: 46235 | F9: 46267 | G9: 0 | H9: No | I9: =IF(OR($E9="",$F9=""),"",IF(AND(I$4<=$F9,I$4+6>=$E9),IF($F9-$E9<=2,"◆",IF($H9="Yes","X",LEFT($D9,1))),"")) | J9: =IF(OR($E9="",$F9=""),"",IF(AND(J$4<=$F9,J$4+6>=$E9),IF($F9-$E9<=2,"◆",IF($H9="Yes","X",LEFT($D9,1))),"")) | K9: =IF(OR($E9="",$F9=""),"",IF(AND(K$4<=$F9,K$4+6>=$E9),IF($F9-$E9<=2,"◆",IF($H9="Yes","X",LEFT($D9,1))),"")) | L9: =IF(OR($E9="",$F9=""),"",IF(AND(L$4<=$F9,L$4+6>=$E9),IF($F9-$E9<=2,"◆",IF($H9="Yes","X",LEFT($D9,1))),"")) | M9: =IF(OR($E9="",$F9=""),"",IF(AND(M$4<=$F9,M$4+6>=$E9),IF($F9-$E9<=2,"◆",IF($H9="Yes","X",LEFT($D9,1))),"")) | N9: =IF(OR($E9="",$F9=""),"",IF(AND(N$4<=$F9,N$4+6>=$E9),IF($F9-$E9<=2,"◆",IF($H9="Yes","X",LEFT($D9,1))),"")) | O9: =IF(OR($E9="",$F9=""),"",IF(AND(O$4<=$F9,O$4+6>=$E9),IF($F9-$E9<=2,"◆",IF($H9="Yes","X",LEFT($D9,1))),"")) | P9: =IF(OR($E9="",$F9=""),"",IF(AND(P$4<=$F9,P$4+6>=$E9),IF($F9-$E9<=2,"◆",IF($H9="Yes","X",LEFT($D9,1))),"")) | ... BI9: =IF(OR($E9="",$F9=""),"",IF(AND(BI$4<=$F9,BI$4+6>=$E9),IF($F9-$E9<=2,"◆",IF($H9="Yes","X",LEFT($D9,1))),""))
A10: T-006 | B10: Build Pipeline for Achievo to be updated | C10: MJ | D10: Not Started | E10: 46282 | F10: 46291 | G10: 0 | H10: No | I10: =IF(OR($E10="",$F10=""),"",IF(AND(I$4<=$F10,I$4+6>=$E10),IF($F10-$E10<=2,"◆",IF($H10="Yes","X",LEFT($D10,1))),"")) | J10: =IF(OR($E10="",$F10=""),"",IF(AND(J$4<=$F10,J$4+6>=$E10),IF($F10-$E10<=2,"◆",IF($H10="Yes","X",LEFT($D10,1))),"")) | K10: =IF(OR($E10="",$F10=""),"",IF(AND(K$4<=$F10,K$4+6>=$E10),IF($F10-$E10<=2,"◆",IF($H10="Yes","X",LEFT($D10,1))),"")) | L10: =IF(OR($E10="",$F10=""),"",IF(AND(L$4<=$F10,L$4+6>=$E10),IF($F10-$E10<=2,"◆",IF($H10="Yes","X",LEFT($D10,1))),"")) | M10: =IF(OR($E10="",$F10=""),"",IF(AND(M$4<=$F10,M$4+6>=$E10),IF($F10-$E10<=2,"◆",IF($H10="Yes","X",LEFT($D10,1))),"")) | N10: =IF(OR($E10="",$F10=""),"",IF(AND(N$4<=$F10,N$4+6>=$E10),IF($F10-$E10<=2,"◆",IF($H10="Yes","X",LEFT($D10,1))),"")) | O10: =IF(OR($E10="",$F10=""),"",IF(AND(O$4<=$F10,O$4+6>=$E10),IF($F10-$E10<=2,"◆",IF($H10="Yes","X",LEFT($D10,1))),"")) | P10: =IF(OR($E10="",$F10=""),"",IF(AND(P$4<=$F10,P$4+6>=$E10),IF($F10-$E10<=2,"◆",IF($H10="Yes","X",LEFT($D10,1))),"")) | ... BI10: =IF(OR($E10="",$F10=""),"",IF(AND(BI$4<=$F10,BI$4+6>=$E10),IF($F10-$E10<=2,"◆",IF($H10="Yes","X",LEFT($D10,1))),""))
A11: T-007 | B11: Integrate the email validation service for Channel Smart 2.0(Roshni to check) | C11: MJ | D11: Not Started | E11: 46257 | F11: 46263 | G11: 0 | H11: No | I11: =IF(OR($E11="",$F11=""),"",IF(AND(I$4<=$F11,I$4+6>=$E11),IF($F11-$E11<=2,"◆",IF($H11="Yes","X",LEFT($D11,1))),"")) | J11: =IF(OR($E11="",$F11=""),"",IF(AND(J$4<=$F11,J$4+6>=$E11),IF($F11-$E11<=2,"◆",IF($H11="Yes","X",LEFT($D11,1))),"")) | K11: =IF(OR($E11="",$F11=""),"",IF(AND(K$4<=$F11,K$4+6>=$E11),IF($F11-$E11<=2,"◆",IF($H11="Yes","X",LEFT($D11,1))),"")) | L11: =IF(OR($E11="",$F11=""),"",IF(AND(L$4<=$F11,L$4+6>=$E11),IF($F11-$E11<=2,"◆",IF($H11="Yes","X",LEFT($D11,1))),"")) | M11: =IF(OR($E11="",$F11=""),"",IF(AND(M$4<=$F11,M$4+6>=$E11),IF($F11-$E11<=2,"◆",IF($H11="Yes","X",LEFT($D11,1))),"")) | N11: =IF(OR($E11="",$F11=""),"",IF(AND(N$4<=$F11,N$4+6>=$E11),IF($F11-$E11<=2,"◆",IF($H11="Yes","X",LEFT($D11,1))),"")) | O11: =IF(OR($E11="",$F11=""),"",IF(AND(O$4<=$F11,O$4+6>=$E11),IF($F11-$E11<=2,"◆",IF($H11="Yes","X",LEFT($D11,1))),"")) | P11: =IF(OR($E11="",$F11=""),"",IF(AND(P$4<=$F11,P$4+6>=$E11),IF($F11-$E11<=2,"◆",IF($H11="Yes","X",LEFT($D11,1))),"")) | ... BI11: =IF(OR($E11="",$F11=""),"",IF(AND(BI$4<=$F11,BI$4+6>=$E11),IF($F11-$E11<=2,"◆",IF($H11="Yes","X",LEFT($D11,1))),""))
A12: T-008 | B12: Build Unsubscribe feature for all the promotional emails(Roshni to check) | C12: MJ | D12: Not Started | E12: 46260 | F12: 46269 | G12: 0 | H12: No | I12: =IF(OR($E12="",$F12=""),"",IF(AND(I$4<=$F12,I$4+6>=$E12),IF($F12-$E12<=2,"◆",IF($H12="Yes","X",LEFT($D12,1))),"")) | J12: =IF(OR($E12="",$F12=""),"",IF(AND(J$4<=$F12,J$4+6>=$E12),IF($F12-$E12<=2,"◆",IF($H12="Yes","X",LEFT($D12,1))),"")) | K12: =IF(OR($E12="",$F12=""),"",IF(AND(K$4<=$F12,K$4+6>=$E12),IF($F12-$E12<=2,"◆",IF($H12="Yes","X",LEFT($D12,1))),"")) | L12: =IF(OR($E12="",$F12=""),"",IF(AND(L$4<=$F12,L$4+6>=$E12),IF($F12-$E12<=2,"◆",IF($H12="Yes","X",LEFT($D12,1))),"")) | M12: =IF(OR($E12="",$F12=""),"",IF(AND(M$4<=$F12,M$4+6>=$E12),IF($F12-$E12<=2,"◆",IF($H12="Yes","X",LEFT($D12,1))),"")) | N12: =IF(OR($E12="",$F12=""),"",IF(AND(N$4<=$F12,N$4+6>=$E12),IF($F12-$E12<=2,"◆",IF($H12="Yes","X",LEFT($D12,1))),"")) | O12: =IF(OR($E12="",$F12=""),"",IF(AND(O$4<=$F12,O$4+6>=$E12),IF($F12-$E12<=2,"◆",IF($H12="Yes","X",LEFT($D12,1))),"")) | P12: =IF(OR($E12="",$F12=""),"",IF(AND(P$4<=$F12,P$4+6>=$E12),IF($F12-$E12<=2,"◆",IF($H12="Yes","X",LEFT($D12,1))),"")) | ... BI12: =IF(OR($E12="",$F12=""),"",IF(AND(BI$4<=$F12,BI$4+6>=$E12),IF($F12-$E12<=2,"◆",IF($H12="Yes","X",LEFT($D12,1))),""))
A13: T-009 | B13: ERP Connerctor Service(Saleforce) | C13: MJ | D13: Not Started | E13: 46204 | F13: 46261 | G13: 0 | H13: No | I13: =IF(OR($E13="",$F13=""),"",IF(AND(I$4<=$F13,I$4+6>=$E13),IF($F13-$E13<=2,"◆",IF($H13="Yes","X",LEFT($D13,1))),"")) | J13: =IF(OR($E13="",$F13=""),"",IF(AND(J$4<=$F13,J$4+6>=$E13),IF($F13-$E13<=2,"◆",IF($H13="Yes","X",LEFT($D13,1))),"")) | K13: =IF(OR($E13="",$F13=""),"",IF(AND(K$4<=$F13,K$4+6>=$E13),IF($F13-$E13<=2,"◆",IF($H13="Yes","X",LEFT($D13,1))),"")) | L13: =IF(OR($E13="",$F13=""),"",IF(AND(L$4<=$F13,L$4+6>=$E13),IF($F13-$E13<=2,"◆",IF($H13="Yes","X",LEFT($D13,1))),"")) | M13: =IF(OR($E13="",$F13=""),"",IF(AND(M$4<=$F13,M$4+6>=$E13),IF($F13-$E13<=2,"◆",IF($H13="Yes","X",LEFT($D13,1))),"")) | N13: =IF(OR($E13="",$F13=""),"",IF(AND(N$4<=$F13,N$4+6>=$E13),IF($F13-$E13<=2,"◆",IF($H13="Yes","X",LEFT($D13,1))),"")) | O13: =IF(OR($E13="",$F13=""),"",IF(AND(O$4<=$F13,O$4+6>=$E13),IF($F13-$E13<=2,"◆",IF($H13="Yes","X",LEFT($D13,1))),"")) | P13: =IF(OR($E13="",$F13=""),"",IF(AND(P$4<=$F13,P$4+6>=$E13),IF($F13-$E13<=2,"◆",IF($H13="Yes","X",LEFT($D13,1))),"")) | ... BI13: =IF(OR($E13="",$F13=""),"",IF(AND(BI$4<=$F13,BI$4+6>=$E13),IF($F13-$E13<=2,"◆",IF($H13="Yes","X",LEFT($D13,1))),""))
A14: T-010 | B14: Technology refresh | C14: Jawahar | D14: In Progress | E14: 46265 | F14: 46277 | G14: 0.29 | H14: No | I14: =IF(OR($E14="",$F14=""),"",IF(AND(I$4<=$F14,I$4+6>=$E14),IF($F14-$E14<=2,"◆",IF($H14="Yes","X",LEFT($D14,1))),"")) | J14: =IF(OR($E14="",$F14=""),"",IF(AND(J$4<=$F14,J$4+6>=$E14),IF($F14-$E14<=2,"◆",IF($H14="Yes","X",LEFT($D14,1))),"")) | K14: =IF(OR($E14="",$F14=""),"",IF(AND(K$4<=$F14,K$4+6>=$E14),IF($F14-$E14<=2,"◆",IF($H14="Yes","X",LEFT($D14,1))),"")) | L14: =IF(OR($E14="",$F14=""),"",IF(AND(L$4<=$F14,L$4+6>=$E14),IF($F14-$E14<=2,"◆",IF($H14="Yes","X",LEFT($D14,1))),"")) | M14: =IF(OR($E14="",$F14=""),"",IF(AND(M$4<=$F14,M$4+6>=$E14),IF($F14-$E14<=2,"◆",IF($H14="Yes","X",LEFT($D14,1))),"")) | N14: =IF(OR($E14="",$F14=""),"",IF(AND(N$4<=$F14,N$4+6>=$E14),IF($F14-$E14<=2,"◆",IF($H14="Yes","X",LEFT($D14,1))),"")) | O14: =IF(OR($E14="",$F14=""),"",IF(AND(O$4<=$F14,O$4+6>=$E14),IF($F14-$E14<=2,"◆",IF($H14="Yes","X",LEFT($D14,1))),"")) | P14: =IF(OR($E14="",$F14=""),"",IF(AND(P$4<=$F14,P$4+6>=$E14),IF($F14-$E14<=2,"◆",IF($H14="Yes","X",LEFT($D14,1))),"")) | ... BI14: =IF(OR($E14="",$F14=""),"",IF(AND(BI$4<=$F14,BI$4+6>=$E14),IF($F14-$E14<=2,"◆",IF($H14="Yes","X",LEFT($D14,1))),""))
A15: T-011 | B15: Fix for Critical Performance Issue(Claims, File Upload) | C15: Jawahar | D15: In Progress | E15: 46271 | F15: 46284 | G15: 0.22 | H15: No | I15: =IF(OR($E15="",$F15=""),"",IF(AND(I$4<=$F15,I$4+6>=$E15),IF($F15-$E15<=2,"◆",IF($H15="Yes","X",LEFT($D15,1))),"")) | J15: =IF(OR($E15="",$F15=""),"",IF(AND(J$4<=$F15,J$4+6>=$E15),IF($F15-$E15<=2,"◆",IF($H15="Yes","X",LEFT($D15,1))),"")) | K15: =IF(OR($E15="",$F15=""),"",IF(AND(K$4<=$F15,K$4+6>=$E15),IF($F15-$E15<=2,"◆",IF($H15="Yes","X",LEFT($D15,1))),"")) | L15: =IF(OR($E15="",$F15=""),"",IF(AND(L$4<=$F15,L$4+6>=$E15),IF($F15-$E15<=2,"◆",IF($H15="Yes","X",LEFT($D15,1))),"")) | M15: =IF(OR($E15="",$F15=""),"",IF(AND(M$4<=$F15,M$4+6>=$E15),IF($F15-$E15<=2,"◆",IF($H15="Yes","X",LEFT($D15,1))),"")) | N15: =IF(OR($E15="",$F15=""),"",IF(AND(N$4<=$F15,N$4+6>=$E15),IF($F15-$E15<=2,"◆",IF($H15="Yes","X",LEFT($D15,1))),"")) | O15: =IF(OR($E15="",$F15=""),"",IF(AND(O$4<=$F15,O$4+6>=$E15),IF($F15-$E15<=2,"◆",IF($H15="Yes","X",LEFT($D15,1))),"")) | P15: =IF(OR($E15="",$F15=""),"",IF(AND(P$4<=$F15,P$4+6>=$E15),IF($F15-$E15<=2,"◆",IF($H15="Yes","X",LEFT($D15,1))),"")) | ... BI15: =IF(OR($E15="",$F15=""),"",IF(AND(BI$4<=$F15,BI$4+6>=$E15),IF($F15-$E15<=2,"◆",IF($H15="Yes","X",LEFT($D15,1))),""))
A16: T-012 | B16: Build a game engine - Requirements | C16: MJ | D16: Not Started | E16: 46208 | F16: 46217 | G16: 0 | H16: No | I16: =IF(OR($E16="",$F16=""),"",IF(AND(I$4<=$F16,I$4+6>=$E16),IF($F16-$E16<=2,"◆",IF($H16="Yes","X",LEFT($D16,1))),"")) | J16: =IF(OR($E16="",$F16=""),"",IF(AND(J$4<=$F16,J$4+6>=$E16),IF($F16-$E16<=2,"◆",IF($H16="Yes","X",LEFT($D16,1))),"")) | K16: =IF(OR($E16="",$F16=""),"",IF(AND(K$4<=$F16,K$4+6>=$E16),IF($F16-$E16<=2,"◆",IF($H16="Yes","X",LEFT($D16,1))),"")) | L16: =IF(OR($E16="",$F16=""),"",IF(AND(L$4<=$F16,L$4+6>=$E16),IF($F16-$E16<=2,"◆",IF($H16="Yes","X",LEFT($D16,1))),"")) | M16: =IF(OR($E16="",$F16=""),"",IF(AND(M$4<=$F16,M$4+6>=$E16),IF($F16-$E16<=2,"◆",IF($H16="Yes","X",LEFT($D16,1))),"")) | N16: =IF(OR($E16="",$F16=""),"",IF(AND(N$4<=$F16,N$4+6>=$E16),IF($F16-$E16<=2,"◆",IF($H16="Yes","X",LEFT($D16,1))),"")) | O16: =IF(OR($E16="",$F16=""),"",IF(AND(O$4<=$F16,O$4+6>=$E16),IF($F16-$E16<=2,"◆",IF($H16="Yes","X",LEFT($D16,1))),"")) | P16: =IF(OR($E16="",$F16=""),"",IF(AND(P$4<=$F16,P$4+6>=$E16),IF($F16-$E16<=2,"◆",IF($H16="Yes","X",LEFT($D16,1))),"")) | ... BI16: =IF(OR($E16="",$F16=""),"",IF(AND(BI$4<=$F16,BI$4+6>=$E16),IF($F16-$E16<=2,"◆",IF($H16="Yes","X",LEFT($D16,1))),""))
... A113: T-109 | B113: Audit Findings remediation | C113: Kadarkarai | D113: At Risk | E113: 46232 | F113: 46236 | G113: 0.21 | H113: No | I113: =IF(OR($E113="",$F113=""),"",IF(AND(I$4<=$F113,I$4+6>=$E113),IF($F113-$E113<=2,"◆",IF($H113="Yes","X",LEFT($D113,1))),"")) | J113: =IF(OR($E113="",$F113=""),"",IF(AND(J$4<=$F113,J$4+6>=$E113),IF($F113-$E113<=2,"◆",IF($H113="Yes","X",LEFT($D113,1))),"")) | K113: =IF(OR($E113="",$F113=""),"",IF(AND(K$4<=$F113,K$4+6>=$E113),IF($F113-$E113<=2,"◆",IF($H113="Yes","X",LEFT($D113,1))),"")) | L113: =IF(OR($E113="",$F113=""),"",IF(AND(L$4<=$F113,L$4+6>=$E113),IF($F113-$E113<=2,"◆",IF($H113="Yes","X",LEFT($D113,1))),"")) | M113: =IF(OR($E113="",$F113=""),"",IF(AND(M$4<=$F113,M$4+6>=$E113),IF($F113-$E113<=2,"◆",IF($H113="Yes","X",LEFT($D113,1))),"")) | N113: =IF(OR($E113="",$F113=""),"",IF(AND(N$4<=$F113,N$4+6>=$E113),IF($F113-$E113<=2,"◆",IF($H113="Yes","X",LEFT($D113,1))),"")) | O113: =IF(OR($E113="",$F113=""),"",IF(AND(O$4<=$F113,O$4+6>=$E113),IF($F113-$E113<=2,"◆",IF($H113="Yes","X",LEFT($D113,1))),"")) | P113: =IF(OR($E113="",$F113=""),"",IF(AND(P$4<=$F113,P$4+6>=$E113),IF($F113-$E113<=2,"◆",IF($H113="Yes","X",LEFT($D113,1))),"")) | ... BI113: =IF(OR($E113="",$F113=""),"",IF(AND(BI$4<=$F113,BI$4+6>=$E113),IF($F113-$E113<=2,"◆",IF($H113="Yes","X",LEFT($D113,1))),""))
A116: MONTHLY VIEW — Task count active per month (formula)
A117: Month | B117: 46204 | C117: 46235 | D117: 46266 | E117: 46296 | F117: 46327 | G117: 46357 | H117: 46388 | I117: 46419 | J117: 46447 | K117: 46478 | L117: 46508 | M117: 46539
B118: =SUMPRODUCT(('Project Tracker'!$N$5:$N$113<=EOMONTH(B$117,0))*('Project Tracker'!$O$5:$O$113>=B$117)*1) | C118: =SUMPRODUCT(('Project Tracker'!$N$5:$N$113<=EOMONTH(C$117,0))*('Project Tracker'!$O$5:$O$113>=C$117)*1) | D118: =SUMPRODUCT(('Project Tracker'!$N$5:$N$113<=EOMONTH(D$117,0))*('Project Tracker'!$O$5:$O$113>=D$117)*1) | E118: =SUMPRODUCT(('Project Tracker'!$N$5:$N$113<=EOMONTH(E$117,0))*('Project Tracker'!$O$5:$O$113>=E$117)*1) | F118: =SUMPRODUCT(('Project Tracker'!$N$5:$N$113<=EOMONTH(F$117,0))*('Project Tracker'!$O$5:$O$113>=F$117)*1) | G118: =SUMPRODUCT(('Project Tracker'!$N$5:$N$113<=EOMONTH(G$117,0))*('Project Tracker'!$O$5:$O$113>=G$117)*1) | H118: =SUMPRODUCT(('Project Tracker'!$N$5:$N$113<=EOMONTH(H$117,0))*('Project Tracker'!$O$5:$O$113>=H$117)*1) | I118: =SUMPRODUCT(('Project Tracker'!$N$5:$N$113<=EOMONTH(I$117,0))*('Project Tracker'!$O$5:$O$113>=I$117)*1) | ... M118: =SUMPRODUCT(('Project Tracker'!$N$5:$N$113<=EOMONTH(M$117,0))*('Project Tracker'!$O$5:$O$113>=M$117)*1)
A121: QUARTERLY VIEW — Active tasks by quarter
B122: FY27-Q1 | C122: FY27-Q2 | D122: FY27-Q3 | E122: FY27-Q4
A123: Start | B123: 46204 | C123: 46296 | D123: 46388 | E123: 46478
A124: End | B124: 46295 | C124: 46387 | D124: 46477 | E124: 46568
A125: Active Tasks | B125: =SUMPRODUCT(('Project Tracker'!$N$5:$N$113<=B124)*('Project Tracker'!$O$5:$O$113>=B123)*1) | C125: =SUMPRODUCT(('Project Tracker'!$N$5:$N$113<=C124)*('Project Tracker'!$O$5:$O$113>=C123)*1) | D125: =SUMPRODUCT(('Project Tracker'!$N$5:$N$113<=D124)*('Project Tracker'!$O$5:$O$113>=D123)*1) | E125: =SUMPRODUCT(('Project Tracker'!$N$5:$N$113<=E124)*('Project Tracker'!$O$5:$O$113>=E123)*1)

Sheet Resource Planning
A1: RESOURCE PLANNING — CAPACITY & UTILIZATION
A2: Allocated Hours roll up from Project Tracker by Owner. Utilization & Overallocation are formula-driven.
A4: Resource | B4: Role | C4: Capacity (h) | D4: Allocated Hours | E4: Remaining Hours | F4: Utilization % | G4: Vacation (h) | H4: Leave (h) | I4: Overallocated?
A5: Jawahar | B5: Tech Lead — Platform / Core | C5: 5900 | D5: =SUMIF('Project Tracker'!$J$5:$J$113,A5,'Project Tracker'!$R$5:$R$113) | E5: =C5-G5-H5-D5 | F5: =IF((C5-G5-H5)=0,0,D5/(C5-G5-H5)) | G5: 80 | H5: 24 | I5: =IF(D5>(C5-G5-H5),"YES","")
A6: Kadarkarai | B6: Engineer — Platform | C6: 1200 | D6: =SUMIF('Project Tracker'!$J$5:$J$113,A6,'Project Tracker'!$R$5:$R$113) | E6: =C6-G6-H6-D6 | F6: =IF((C6-G6-H6)=0,0,D6/(C6-G6-H6)) | G6: 40 | H6: 24 | I6: =IF(D6>(C6-G6-H6),"YES","")
A7: MJ | B7: EM / Tech Lead — CS | C7: 6850 | D7: =SUMIF('Project Tracker'!$J$5:$J$113,A7,'Project Tracker'!$R$5:$R$113) | E7: =C7-G7-H7-D7 | F7: =IF((C7-G7-H7)=0,0,D7/(C7-G7-H7)) | G7: 80 | H7: 24 | I7: =IF(D7>(C7-G7-H7),"YES","")
A8: Shriguru | B8: Engineer — Achievo / Rewards | C8: 1200 | D8: =SUMIF('Project Tracker'!$J$5:$J$113,A8,'Project Tracker'!$R$5:$R$113) | E8: =C8-G8-H8-D8 | F8: =IF((C8-G8-H8)=0,0,D8/(C8-G8-H8)) | G8: 40 | H8: 24 | I8: =IF(D8>(C8-G8-H8),"YES","")
A9: Siva | B9: Tech Lead — Data / PIS | C9: 3150 | D9: =SUMIF('Project Tracker'!$J$5:$J$113,A9,'Project Tracker'!$R$5:$R$113) | E9: =C9-G9-H9-D9 | F9: =IF((C9-G9-H9)=0,0,D9/(C9-G9-H9)) | G9: 80 | H9: 24 | I9: =IF(D9>(C9-G9-H9),"YES","")
A12: MONTHLY ALLOCATION (Planned Hours by Owner × Month)
A13: Resource | B13: 46204 | C13: 46235 | D13: 46266 | E13: 46296 | F13: 46327 | G13: 46357 | H13: 46388 | I13: 46419 | J13: 46447 | K13: 46478 | L13: 46508 | M13: 46539
A14: Jawahar | B14: =SUMPRODUCT(('Project Tracker'!$J$5:$J$113=A14)*('Project Tracker'!$N$5:$N$113<=EOMONTH(B$13,0))*('Project Tracker'!$O$5:$O$113>=B$13)*('Project Tracker'!$R$5:$R$113)) | C14: =SUMPRODUCT(('Project Tracker'!$J$5:$J$113=A14)*('Project Tracker'!$N$5:$N$113<=EOMONTH(C$13,0))*('Project Tracker'!$O$5:$O$113>=C$13)*('Project Tracker'!$R$5:$R$113)) | D14: =SUMPRODUCT(('Project Tracker'!$J$5:$J$113=A14)*('Project Tracker'!$N$5:$N$113<=EOMONTH(D$13,0))*('Project Tracker'!$O$5:$O$113>=D$13)*('Project Tracker'!$R$5:$R$113)) | E14: =SUMPRODUCT(('Project Tracker'!$J$5:$J$113=A14)*('Project Tracker'!$N$5:$N$113<=EOMONTH(E$13,0))*('Project Tracker'!$O$5:$O$113>=E$13)*('Project Tracker'!$R$5:$R$113)) | F14: =SUMPRODUCT(('Project Tracker'!$J$5:$J$113=A14)*('Project Tracker'!$N$5:$N$113<=EOMONTH(F$13,0))*('Project Tracker'!$O$5:$O$113>=F$13)*('Project Tracker'!$R$5:$R$113)) | G14: =SUMPRODUCT(('Project Tracker'!$J$5:$J$113=A14)*('Project Tracker'!$N$5:$N$113<=EOMONTH(G$13,0))*('Project Tracker'!$O$5:$O$113>=G$13)*('Project Tracker'!$R$5:$R$113)) | H14: =SUMPRODUCT(('Project Tracker'!$J$5:$J$113=A14)*('Project Tracker'!$N$5:$N$113<=EOMONTH(H$13,0))*('Project Tracker'!$O$5:$O$113>=H$13)*('Project Tracker'!$R$5:$R$113)) | I14: =SUMPRODUCT(('Project Tracker'!$J$5:$J$113=A14)*('Project Tracker'!$N$5:$N$113<=EOMONTH(I$13,0))*('Project Tracker'!$O$5:$O$113>=I$13)*('Project Tracker'!$R$5:$R$113)) | J14: =SUMPRODUCT(('Project Tracker'!$J$5:$J$113=A14)*('Project Tracker'!$N$5:$N$113<=EOMONTH(J$13,0))*('Project Tracker'!$O$5:$O$113>=J$13)*('Project Tracker'!$R$5:$R$113)) | K14: =SUMPRODUCT(('Project Tracker'!$J$5:$J$113=A14)*('Project Tracker'!$N$5:$N$113<=EOMONTH(K$13,0))*('Project Tracker'!$O$5:$O$113>=K$13)*('Project Tracker'!$R$5:$R$113)) | L14: =SUMPRODUCT(('Project Tracker'!$J$5:$J$113=A14)*('Project Tracker'!$N$5:$N$113<=EOMONTH(L$13,0))*('Project Tracker'!$O$5:$O$113>=L$13)*('Project Tracker'!$R$5:$R$113)) | M14: =SUMPRODUCT(('Project Tracker'!$J$5:$J$113=A14)*('Project Tracker'!$N$5:$N$113<=EOMONTH(M$13,0))*('Project Tracker'!$O$5:$O$113>=M$13)*('Project Tracker'!$R$5:$R$113))
A15: Kadarkarai | B15: =SUMPRODUCT(('Project Tracker'!$J$5:$J$113=A15)*('Project Tracker'!$N$5:$N$113<=EOMONTH(B$13,0))*('Project Tracker'!$O$5:$O$113>=B$13)*('Project Tracker'!$R$5:$R$113)) | C15: =SUMPRODUCT(('Project Tracker'!$J$5:$J$113=A15)*('Project Tracker'!$N$5:$N$113<=EOMONTH(C$13,0))*('Project Tracker'!$O$5:$O$113>=C$13)*('Project Tracker'!$R$5:$R$113)) | D15: =SUMPRODUCT(('Project Tracker'!$J$5:$J$113=A15)*('Project Tracker'!$N$5:$N$113<=EOMONTH(D$13,0))*('Project Tracker'!$O$5:$O$113>=D$13)*('Project Tracker'!$R$5:$R$113)) | E15: =SUMPRODUCT(('Project Tracker'!$J$5:$J$113=A15)*('Project Tracker'!$N$5:$N$113<=EOMONTH(E$13,0))*('Project Tracker'!$O$5:$O$113>=E$13)*('Project Tracker'!$R$5:$R$113)) | F15: =SUMPRODUCT(('Project Tracker'!$J$5:$J$113=A15)*('Project Tracker'!$N$5:$N$113<=EOMONTH(F$13,0))*('Project Tracker'!$O$5:$O$113>=F$13)*('Project Tracker'!$R$5:$R$113)) | G15: =SUMPRODUCT(('Project Tracker'!$J$5:$J$113=A15)*('Project Tracker'!$N$5:$N$113<=EOMONTH(G$13,0))*('Project Tracker'!$O$5:$O$113>=G$13)*('Project Tracker'!$R$5:$R$113)) | H15: =SUMPRODUCT(('Project Tracker'!$J$5:$J$113=A15)*('Project Tracker'!$N$5:$N$113<=EOMONTH(H$13,0))*('Project Tracker'!$O$5:$O$113>=H$13)*('Project Tracker'!$R$5:$R$113)) | I15: =SUMPRODUCT(('Project Tracker'!$J$5:$J$113=A15)*('Project Tracker'!$N$5:$N$113<=EOMONTH(I$13,0))*('Project Tracker'!$O$5:$O$113>=I$13)*('Project Tracker'!$R$5:$R$113)) | J15: =SUMPRODUCT(('Project Tracker'!$J$5:$J$113=A15)*('Project Tracker'!$N$5:$N$113<=EOMONTH(J$13,0))*('Project Tracker'!$O$5:$O$113>=J$13)*('Project Tracker'!$R$5:$R$113)) | K15: =SUMPRODUCT(('Project Tracker'!$J$5:$J$113=A15)*('Project Tracker'!$N$5:$N$113<=EOMONTH(K$13,0))*('Project Tracker'!$O$5:$O$113>=K$13)*('Project Tracker'!$R$5:$R$113)) | L15: =SUMPRODUCT(('Project Tracker'!$J$5:$J$113=A15)*('Project Tracker'!$N$5:$N$113<=EOMONTH(L$13,0))*('Project Tracker'!$O$5:$O$113>=L$13)*('Project Tracker'!$R$5:$R$113)) | M15: =SUMPRODUCT(('Project Tracker'!$J$5:$J$113=A15)*('Project Tracker'!$N$5:$N$113<=EOMONTH(M$13,0))*('Project Tracker'!$O$5:$O$113>=M$13)*('Project Tracker'!$R$5:$R$113))
A16: MJ | B16: =SUMPRODUCT(('Project Tracker'!$J$5:$J$113=A16)*('Project Tracker'!$N$5:$N$113<=EOMONTH(B$13,0))*('Project Tracker'!$O$5:$O$113>=B$13)*('Project Tracker'!$R$5:$R$113)) | C16: =SUMPRODUCT(('Project Tracker'!$J$5:$J$113=A16)*('Project Tracker'!$N$5:$N$113<=EOMONTH(C$13,0))*('Project Tracker'!$O$5:$O$113>=C$13)*('Project Tracker'!$R$5:$R$113)) | D16: =SUMPRODUCT(('Project Tracker'!$J$5:$J$113=A16)*('Project Tracker'!$N$5:$N$113<=EOMONTH(D$13,0))*('Project Tracker'!$O$5:$O$113>=D$13)*('Project Tracker'!$R$5:$R$113)) | E16: =SUMPRODUCT(('Project Tracker'!$J$5:$J$113=A16)*('Project Tracker'!$N$5:$N$113<=EOMONTH(E$13,0))*('Project Tracker'!$O$5:$O$113>=E$13)*('Project Tracker'!$R$5:$R$113)) | F16: =SUMPRODUCT(('Project Tracker'!$J$5:$J$113=A16)*('Project Tracker'!$N$5:$N$113<=EOMONTH(F$13,0))*('Project Tracker'!$O$5:$O$113>=F$13)*('Project Tracker'!$R$5:$R$113)) | G16: =SUMPRODUCT(('Project Tracker'!$J$5:$J$113=A16)*('Project Tracker'!$N$5:$N$113<=EOMONTH(G$13,0))*('Project Tracker'!$O$5:$O$113>=G$13)*('Project Tracker'!$R$5:$R$113)) | H16: =SUMPRODUCT(('Project Tracker'!$J$5:$J$113=A16)*('Project Tracker'!$N$5:$N$113<=EOMONTH(H$13,0))*('Project Tracker'!$O$5:$O$113>=H$13)*('Project Tracker'!$R$5:$R$113)) | I16: =SUMPRODUCT(('Project Tracker'!$J$5:$J$113=A16)*('Project Tracker'!$N$5:$N$113<=EOMONTH(I$13,0))*('Project Tracker'!$O$5:$O$113>=I$13)*('Project Tracker'!$R$5:$R$113)) | J16: =SUMPRODUCT(('Project Tracker'!$J$5:$J$113=A16)*('Project Tracker'!$N$5:$N$113<=EOMONTH(J$13,0))*('Project Tracker'!$O$5:$O$113>=J$13)*('Project Tracker'!$R$5:$R$113)) | K16: =SUMPRODUCT(('Project Tracker'!$J$5:$J$113=A16)*('Project Tracker'!$N$5:$N$113<=EOMONTH(K$13,0))*('Project Tracker'!$O$5:$O$113>=K$13)*('Project Tracker'!$R$5:$R$113)) | L16: =SUMPRODUCT(('Project Tracker'!$J$5:$J$113=A16)*('Project Tracker'!$N$5:$N$113<=EOMONTH(L$13,0))*('Project Tracker'!$O$5:$O$113>=L$13)*('Project Tracker'!$R$5:$R$113)) | M16: =SUMPRODUCT(('Project Tracker'!$J$5:$J$113=A16)*('Project Tracker'!$N$5:$N$113<=EOMONTH(M$13,0))*('Project Tracker'!$O$5:$O$113>=M$13)*('Project Tracker'!$R$5:$R$113))
